<?xml version="1.0"?>
<robot name="robot" xmlns:xacro="http://www.ros.org/wiki/xacro">

    <xacro:property name="urdf_data" value="${load_yaml('$(find lab3)/config/urdf_params.yaml')}"/>

    <xacro:property name="box_size" value="0.05"/>
	<xacro:property name="base_box_size" value="0.3"/>
    <xacro:property name="last_link_len" value="0.1"/>  
    <xacro:property name="last_link_radius" value="0.03"/>    

 
    <material name="yellow"> 
        <color rgba="1 1 0 1"/>
    </material>
    <material name="blue">
        <color rgba="0 0.7 1 1"/>
    </material>


    <link name="base_link">
        <visual>
            <geometry>
				<box size="${base_box_size} ${base_box_size} ${base_box_size} "/>
            </geometry>
			<origin xyz="0 0 0"/>
            <material name="yellow"/>
        </visual>
    </link>

    <link name="link1">
        <visual>
            <geometry>
				<box size="${box_size} ${box_size} ${urdf_data['i1']['l_len']} "/>
            </geometry>
			<origin xyz="0 0 ${-urdf_data['i1']['l_len']/2}" rpy="${urdf_data['i1']['l_rpy']}"/>
            <material name="blue"/>
        </visual>
    </link>

    <link name="link2">
        <visual>
            <geometry>
				<box size="${box_size} ${box_size} ${urdf_data['i2']['l_len']}"/>
            </geometry>
			<origin xyz="0 0 ${-urdf_data['i2']['l_len']/2}" rpy="${urdf_data['i2']['l_rpy']}"/>
            <material name="yellow"/>
        </visual>
    </link>

    <link name="link3">
        <visual>
            <geometry>
				<box size="${box_size} ${box_size} ${urdf_data['i3']['l_len']}"/>
            </geometry>
			<origin xyz="0 0 ${-urdf_data ['i3']['l_len']/2}" rpy="${urdf_data['i3']['l_rpy']}"/>
            <material name="blue"/>
        </visual>
    </link>
	
	<link name="gripper">
        <visual>
            <geometry>
                <cylinder length="${last_link_len}" radius="${last_link_radius}"/>
            </geometry>
			<origin xyz="0 0 0" rpy="0 0 0"/>
            <material name="yellow"/>
        </visual>
    </link>

	<joint name="base_link_link1" type="prismatic">
    	<axis xyz="0 0 1"/>
    	<limit effort="1000.0" lower="-1" upper="0" velocity="0.5"/>

        <parent link="base_link"/>
        <child link="link1"/>
		<origin xyz="${urdf_data['i1']['j_xyz']}" rpy="${urdf_data['i1']['j_rpy']}"/>
    </joint>

    <joint name="link1_link2" type="prismatic">
    	<axis xyz="0 0 1"/>
    	<limit effort="1000.0" lower="-1" upper="0" velocity="0.5"/>
        <parent link="link1"/>
        <child link="link2"/>
        <origin xyz="${urdf_data['i2']['j_xyz']}" rpy="${urdf_data['i2']['j_rpy']}"/>
    </joint>

    <joint name="link2_link3" type="prismatic">
    	<axis xyz="0 0 1"/>
    	<limit effort="1000.0" lower="-1" upper="0" velocity="0.5"/>
        <parent link="link2"/>
        <child link="link3"/>
        <origin xyz="${urdf_data['i3']['j_xyz']}" rpy="${urdf_data['i2']['j_rpy']}"/>
    </joint>

    <joint name="link3_gripper" type="fixed">
        <parent link="link3"/>
        <child link="gripper"/>
		<origin xyz="0 0 0" rpy="0 0 0"/>
    </joint>
</robot>
